Workbook

Sheet Ringkasan
B1: INDEKS BEBAN TUGAS BERWAJARAN: NEGERI BESAR KEMAS
B2: Kerangka wajaran HQ (fail negeri sederhana v3) digunakan ke atas Sarawak, Sabah, Johor dan Perak. Indeks 1.00 = purata 5 negeri sederhana (Selangor, Kedah, Pahang, Terengganu, Kelantan).
B3: Versi 1.3 | 23 September 2026 | Kumpulan 4 Negeri Besar | Data agregat sahaja (tiada data peribadi)
B5: PANEL KAWALAN (ubah sel kuning sahaja; semua sheet dikira semula secara automatik)
B6: Sumber garis asas | C6: Nasional | D6: Nasional (lalai) = satu sumber kebangsaan untuk semua 9 negeri jika ada (BPAK Mei 2026, PPPAK, PKEM 2026, DOSM). Data HQ = nilai negeri sederhana seperti dalam fail HQ; negeri besar guna data negeri (L1).
B7: Had nisbah maksimum | C7: 99 | D7: 99 = tiada had. Uji 3.0 untuk hadkan kesan nilai ekstrem (contoh: kampung Sarawak, keluasan Sarawak).
B8: Minimum negeri sederhana untuk garis asas sah | C8: 3 | D8: Garis asas sub-kriteria sah hanya jika sekurang-kurangnya bilangan ini negeri sederhana mempunyai nilai berangka.
B9: Wajaran Pendidikan Awal Kanak-Kanak (HQ) | C9: 0.2 | D9: Wajaran asal HQ.
B10: Wajaran Kemahiran (HQ) | C10: 0.15 | D10: Wajaran asal HQ.
B11: Wajaran Komuniti (HQ) | C11: 0.15 | D11: Wajaran asal HQ.
B12: Wajaran Pengurusan (HQ) | C12: 0.5 | D12: Wajaran asal HQ.
B13: Jumlah wajaran HQ (semakan) | C13: =SUM(C9:C12) -> 1 | D13: =IF(ABS(C13-1)<0.00001,"OK: jumlah wajaran 100%","SEMAK: jumlah wajaran bukan 100%") -> OK: jumlah wajaran 100%
B14: Wajaran keluasan kawasan (Senario B) | C14: 0.1 | D14: Cadangan Kumpulan 4. Wajaran HQ didarab (1 - nilai ini) dalam Senario B.
B16: KEPUTUSAN (dikira daripada sheet Skor Senario A dan Senario B Geografi)
B17: Negeri | C17: Kategori | D17: Indeks Senario A (wajaran HQ) | E17: Kedudukan A | F17: Indeks Senario B (+ keluasan) | G17: Kedudukan B | H17: Indeks tanpa Pengurusan | I17: Sub-kriteria diskor (/23) | J17: Liputan berwajaran
B18: Sarawak | C18: Negeri besar | D18: ='Skor Senario A'!I38 -> 2.1751619 | E18: ='Skor Senario A'!I39 -> 1 | F18: ='Senario B Geografi'!D20 -> 2.7176458 | G18: ='Senario B Geografi'!D21 -> 1 | H18: ='Skor Senario A'!I42 -> 2.2238989 | I18: ='Skor Senario A'!I40 -> 17 | J18: ='Skor Senario A'!I41 -> 0.60535714
B19: Sabah | C19: Negeri besar | D19: ='Skor Senario A'!J38 -> 1.6796733 | E19: ='Skor Senario A'!J39 -> 2 | F19: ='Senario B Geografi'!E20 -> 1.9630281 | G19: ='Senario B Geografi'!E21 -> 2 | H19: ='Skor Senario A'!J42 -> 1.94058 | I19: ='Skor Senario A'!J40 -> 17 | J19: ='Skor Senario A'!J41 -> 0.60535714
B20: Johor | C20: Negeri besar | D20: ='Skor Senario A'!K38 -> 1.1525912 | E20: ='Skor Senario A'!K39 -> 5 | F20: ='Senario B Geografi'!F20 -> 1.154645 | G20: ='Senario B Geografi'!F21 -> 5 | H20: ='Skor Senario A'!K42 -> 1.5511037 | I20: ='Skor Senario A'!K40 -> 17 | J20: ='Skor Senario A'!K41 -> 0.60535714
B21: Perak | C21: Negeri besar | D21: ='Skor Senario A'!L38 -> 1.4753356 | E21: ='Skor Senario A'!L39 -> 3 | F21: ='Senario B Geografi'!G20 -> 1.45626 | G21: ='Senario B Geografi'!G21 -> 3 | H21: ='Skor Senario A'!L42 -> 1.3094327 | I21: ='Skor Senario A'!L40 -> 17 | J21: ='Skor Senario A'!L41 -> 0.60535714
B22: Selangor | C22: Negeri sederhana | D22: ='Skor Senario A'!M38 -> 1.2214652 | E22: ='Skor Senario A'!M39 -> 4 | F22: ='Senario B Geografi'!H20 -> 1.1488088 | G22: ='Senario B Geografi'!H21 -> 6 | H22: ='Skor Senario A'!M42 -> 1.1863195 | I22: ='Skor Senario A'!M40 -> 17 | J22: ='Skor Senario A'!M41 -> 0.60535714
B23: Kedah | C23: Negeri sederhana | D23: ='Skor Senario A'!N38 -> 1.1200029 | E23: ='Skor Senario A'!N39 -> 6 | F23: ='Senario B Geografi'!I20 -> 1.0660179 | G23: ='Senario B Geografi'!I21 -> 7 | H23: ='Skor Senario A'!N42 -> 1.1249017 | I23: ='Skor Senario A'!N40 -> 16 | J23: ='Skor Senario A'!N41 -> 0.56785714
B24: Pahang | C24: Negeri sederhana | D24: ='Skor Senario A'!O38 -> 1.0647537 | E24: ='Skor Senario A'!O39 -> 7 | F24: ='Senario B Geografi'!J20 -> 1.1789623 | G24: ='Senario B Geografi'!J21 -> 4 | H24: ='Skor Senario A'!O42 -> 0.98007785 | I24: ='Skor Senario A'!O40 -> 16 | J24: ='Skor Senario A'!O41 -> 0.56785714
B25: Terengganu | C25: Negeri sederhana | D25: ='Skor Senario A'!P38 -> 0.91250007 | E25: ='Skor Senario A'!P39 -> 8 | F25: ='Senario B Geografi'!K20 -> 0.90085311 | G25: ='Senario B Geografi'!K21 -> 8 | H25: ='Skor Senario A'!P42 -> 0.80927933 | I25: ='Skor Senario A'!P40 -> 17 | J25: ='Skor Senario A'!P41 -> 0.60535714
B26: Kelantan | C26: Negeri sederhana | D26: ='Skor Senario A'!Q38 -> 0.68929827 | E26: ='Skor Senario A'!Q39 -> 9 | F26: ='Senario B Geografi'!L20 -> 0.71257608 | G26: ='Senario B Geografi'!L21 -> 9 | H26: ='Skor Senario A'!Q42 -> 0.91546185 | I26: ='Skor Senario A'!Q40 -> 17 | J26: ='Skor Senario A'!Q41 -> 0.60535714
B27: Purata 5 negeri sederhana | D27: =AVERAGE(D22:D26) -> 1.001604 | F27: =AVERAGE(F22:F26) -> 1.0014436 | H27: =AVERAGE(H22:H26) -> 1.0032081 | I27: =AVERAGE(I22:I26) -> 16.6 | J27: =AVERAGE(J22:J26) -> 0.59035714
B28: Purata 4 negeri besar | D28: =AVERAGE(D18:D21) -> 1.6206905 | F28: =AVERAGE(F18:F21) -> 1.8228947 | H28: =AVERAGE(H18:H21) -> 1.7562538 | I28: =AVERAGE(I18:I21) -> 17 | J28: =AVERAGE(J18:J21) -> 0.60535714
B29: ="Tafsiran: Senario A, Sarawak "&TEXT(D18,"0.00")&"x, Sabah "&TEXT(D19,"0.00")&"x, Johor "&TEXT(D20,"0.00")&"x dan Perak "&TEXT(D21,"0.00")&"x purata negeri sederhana. Senario B: "&TEXT(F18,"0.00")&"x, "&TEXT(F19,"0.00")&"x, "&TEXT(F20,"0.00")&"x dan "&TEXT(F21,"0.00")&"x. Liputan data: "&TEXT(J18,"0%")&" kerangka HQ (ikut wajaran)." -> Tafsiran: Senario A, Sarawak 2.18x, Sabah 1.68x, Johor 1.15x dan Perak 1.48x purata negeri sederhana. Senario B: 2.72x, 1.96x, 1.15x dan 1.46x. Liputan data: 61% kerangka HQ (ikut wajaran).
B52: CATATAN UTAMA
B53: 1 TAFSIRAN INDEKS | C53: Indeks 1.00 = purata 5 negeri sederhana dalam fail HQ. Indeks 2.00 bermaksud beban tugas berwajaran dua kali ganda purata negeri sederhana.
B54: 2 ASAS SKOR | C54: Skor dikira hanya pada sub-kriteria yang ada data untuk keempat-empat negeri besar dan sekurang-kurangnya 3 negeri sederhana (parameter; set yang sama untuk 9 negeri). Sub-kriteria lain ditanda [DATA BELUM DIKEMUKAKAN] dan diminta melalui sheet Borang Negeri; indeks dikira semula secara automatik apabila borang diisi.
B55: 3 PENGURUSAN 50% | C55: Pengurusan (50%) kini diwakili oleh perjawatan sahaja kerana data aset, bajet, baucer dan projek belum ada (dan HQ sendiri hanya ada 1 hingga 2 negeri sederhana). Rujuk lajur Indeks tanpa Pengurusan sebagai semakan kepekaan.
B56: 4 SUIS SUMBER | C56: Suis Sumber garis asas: Nasional (lalai) guna satu sumber kebangsaan untuk semua 9 negeri; Data HQ guna nilai negeri sederhana seperti dalam fail HQ.
B57: 5 SENARIO B | C57: Senario B ialah cadangan Kumpulan 4 (faktor keluasan 10%), bukan sebahagian kerangka HQ asal.
B58: 6 SABAH DAN JOHOR | C58: Sabah: kampung ialah had bawah (4 daerah dan kampung Semporna belum diisi dalam L1). Perjawatan Sabah dan Johor ialah anggaran L4; Sabah belum disahkan.
B59: 7 RUJUKAN | C59: Butiran kaedah, sumber dan had data: sheet Kaedah & Sumber.

Sheet Matriks Negeri Besar
A1: MATRIKS WAJARAN NEGERI BESAR (FORMAT HQ)
A2: ="Kerangka: HQ - wajaran negeri sederhana v3 | Sumber garis asas: "&P_SUMBER&" | Nilai dipautkan dari sheet Data 9 Negeri (blok D)" -> Kerangka: HQ - wajaran negeri sederhana v3 | Sumber garis asas: Nasional | Nilai dipautkan dari sheet Data 9 Negeri (blok D)
D4: Negeri
A5: Bil. | B5: Kriteria | C5: Sub Kriteria | D5: Sarawak | E5: Sabah | F5: Johor | G5: Perak | H5: Wajaran | I5: Penerangan | J5: Sumber data dan catatan | K5: Purata 5 negeri sederhana (garis asas) | L5: Diskor?
A6: 1 | B6: Pendidikan Awal Kanak-Kanak | C6: Bilangan kelas TABIKA | D6: =IF(ISNUMBER('Data 9 Negeri'!D80),'Data 9 Negeri'!D80,"[DATA BELUM DIKEMUKAKAN]") -> 1300 | E6: =IF(ISNUMBER('Data 9 Negeri'!E80),'Data 9 Negeri'!E80,"[DATA BELUM DIKEMUKAKAN]") -> 1402 | F6: =IF(ISNUMBER('Data 9 Negeri'!F80),'Data 9 Negeri'!F80,"[DATA BELUM DIKEMUKAKAN]") -> 1162 | G6: =IF(ISNUMBER('Data 9 Negeri'!G80),'Data 9 Negeri'!G80,"[DATA BELUM DIKEMUKAKAN]") -> 804 | H6: =W_PAKK -> 0.2 | I6: Jumlah kelas TABIKA yang perlu diurus, diselia dan dipantau. | J6: BPAK Data Kelas TABIKA 2026 (Mei 2026). | K6: =IF(ISNUMBER('Skor Senario A'!D6),'Skor Senario A'!D6,"Belum sah (data HQ kurang)") -> 860.6 | L6: ='Skor Senario A'!H6 -> YA
C7: Bilangan kelas TASKA | D7: =IF(ISNUMBER('Data 9 Negeri'!D81),'Data 9 Negeri'!D81,"[DATA BELUM DIKEMUKAKAN]") -> 85 | E7: =IF(ISNUMBER('Data 9 Negeri'!E81),'Data 9 Negeri'!E81,"[DATA BELUM DIKEMUKAKAN]") -> 67 | F7: =IF(ISNUMBER('Data 9 Negeri'!F81),'Data 9 Negeri'!F81,"[DATA BELUM DIKEMUKAKAN]") -> 59 | G7: =IF(ISNUMBER('Data 9 Negeri'!G81),'Data 9 Negeri'!G81,"[DATA BELUM DIKEMUKAKAN]") -> 44 | I7: Jumlah kelas TASKA yang perlu diurus, diselia dan dipantau. | J7: BPAK Data Kelas TASKA 2026 (Mei 2026). | K7: =IF(ISNUMBER('Skor Senario A'!D7),'Skor Senario A'!D7,"Belum sah (data HQ kurang)") -> 39.6 | L7: ='Skor Senario A'!H7 -> YA
C8: Bilangan guru TABIKA | D8: =IF(ISNUMBER('Data 9 Negeri'!D82),'Data 9 Negeri'!D82,"[DATA BELUM DIKEMUKAKAN]") -> 1291 | E8: =IF(ISNUMBER('Data 9 Negeri'!E82),'Data 9 Negeri'!E82,"[DATA BELUM DIKEMUKAKAN]") -> 1349 | F8: =IF(ISNUMBER('Data 9 Negeri'!F82),'Data 9 Negeri'!F82,"[DATA BELUM DIKEMUKAKAN]") -> 1043 | G8: =IF(ISNUMBER('Data 9 Negeri'!G82),'Data 9 Negeri'!G82,"[DATA BELUM DIKEMUKAKAN]") -> 757 | I8: Jumlah tenaga pengajar yang berada di bawah penyeliaan TABIKA | J8: BPAK: jumlah PM TABIKA gred S5 + S1 (kontrak dan JSKT). | K8: =IF(ISNUMBER('Skor Senario A'!D8),'Skor Senario A'!D8,"Belum sah (data HQ kurang)") -> 819 | L8: ='Skor Senario A'!H8 -> YA
C9: Bilangan guru TASKA | D9: =IF(ISNUMBER('Data 9 Negeri'!D83),'Data 9 Negeri'!D83,"[DATA BELUM DIKEMUKAKAN]") -> 249 | E9: =IF(ISNUMBER('Data 9 Negeri'!E83),'Data 9 Negeri'!E83,"[DATA BELUM DIKEMUKAKAN]") -> 206 | F9: =IF(ISNUMBER('Data 9 Negeri'!F83),'Data 9 Negeri'!F83,"[DATA BELUM DIKEMUKAKAN]") -> 179 | G9: =IF(ISNUMBER('Data 9 Negeri'!G83),'Data 9 Negeri'!G83,"[DATA BELUM DIKEMUKAKAN]") -> 149 | I9: Jumlah tenaga pengajar yang berada di bawah penyeliaan TASKA (†) | J9: BPAK: jumlah PM TASKA gred S5 + S1 (kontrak dan JSKT). | K9: =IF(ISNUMBER('Skor Senario A'!D9),'Skor Senario A'!D9,"Belum sah (data HQ kurang)") -> 140.2 | L9: ='Skor Senario A'!H9 -> YA
C10: Bilangan pembantu | D10: =IF(ISNUMBER('Data 9 Negeri'!D84),'Data 9 Negeri'!D84,"[DATA BELUM DIKEMUKAKAN]") -> 1263 | E10: =IF(ISNUMBER('Data 9 Negeri'!E84),'Data 9 Negeri'!E84,"[DATA BELUM DIKEMUKAKAN]") -> 1465 | F10: =IF(ISNUMBER('Data 9 Negeri'!F84),'Data 9 Negeri'!F84,"[DATA BELUM DIKEMUKAKAN]") -> 1223 | G10: =IF(ISNUMBER('Data 9 Negeri'!G84),'Data 9 Negeri'!G84,"[DATA BELUM DIKEMUKAKAN]") -> 849 | I10: Jumlah tenaga pembantu yang berada di bawah penyeliaan | J10: Borang B1 diisi lengkap oleh Sarawak, Sabah, Johor dan Perak (disahkan Sept 2026). Rujukan L4 (tidak setara takrif HQ): Sarawak 19, Sabah ±19, Johor 7, Perak 2. | K10: =IF(ISNUMBER('Skor Senario A'!D10),'Skor Senario A'!D10,"Belum sah (data HQ kurang)") -> 892.6 | L10: ='Skor Senario A'!H10 -> YA
C11: Bilangan murid TABIKA | D11: =IF(ISNUMBER('Data 9 Negeri'!D85),'Data 9 Negeri'!D85,"[DATA BELUM DIKEMUKAKAN]") -> 16243 | E11: =IF(ISNUMBER('Data 9 Negeri'!E85),'Data 9 Negeri'!E85,"[DATA BELUM DIKEMUKAKAN]") -> 26211 | F11: =IF(ISNUMBER('Data 9 Negeri'!F85),'Data 9 Negeri'!F85,"[DATA BELUM DIKEMUKAKAN]") -> 23984 | G11: =IF(ISNUMBER('Data 9 Negeri'!G85),'Data 9 Negeri'!G85,"[DATA BELUM DIKEMUKAKAN]") -> 15211 | I11: Jumlah murid yang menerima perkhidmatan pendidikan awal kanak-kanak (TABIKA) | J11: Borang B2 diisi lengkap oleh Sarawak, Sabah, Johor dan Perak (disahkan Sept 2026). | K11: =IF(ISNUMBER('Skor Senario A'!D11),'Skor Senario A'!D11,"Belum sah (data HQ kurang)") -> 18423.4 | L11: ='Skor Senario A'!H11 -> YA
C12: Bilangan murid TASKA | D12: =IF(ISNUMBER('Data 9 Negeri'!D86),'Data 9 Negeri'!D86,"[DATA BELUM DIKEMUKAKAN]") -> 1209 | E12: =IF(ISNUMBER('Data 9 Negeri'!E86),'Data 9 Negeri'!E86,"[DATA BELUM DIKEMUKAKAN]") -> 1397 | F12: =IF(ISNUMBER('Data 9 Negeri'!F86),'Data 9 Negeri'!F86,"[DATA BELUM DIKEMUKAKAN]") -> 1104 | G12: =IF(ISNUMBER('Data 9 Negeri'!G86),'Data 9 Negeri'!G86,"[DATA BELUM DIKEMUKAKAN]") -> 878 | I12: Jumlah murid yang menerima perkhidmatan pendidikan awal kanak-kanak (TASKA) | J12: Borang B3 diisi lengkap oleh Sarawak, Sabah, Johor dan Perak (disahkan Sept 2026). | K12: =IF(ISNUMBER('Skor Senario A'!D12),'Skor Senario A'!D12,"Belum sah (data HQ kurang)") -> 795.8 | L12: ='Skor Senario A'!H12 -> YA
C13: Bilangan penyelia daerah | D13: =IF(ISNUMBER('Data 9 Negeri'!D87),'Data 9 Negeri'!D87,"[DATA BELUM DIKEMUKAKAN]") -> 37 | E13: =IF(ISNUMBER('Data 9 Negeri'!E87),'Data 9 Negeri'!E87,"[DATA BELUM DIKEMUKAKAN]") -> 36 | F13: =IF(ISNUMBER('Data 9 Negeri'!F87),'Data 9 Negeri'!F87,"[DATA BELUM DIKEMUKAKAN]") -> 20 | G13: =IF(ISNUMBER('Data 9 Negeri'!G87),'Data 9 Negeri'!G87,"[DATA BELUM DIKEMUKAKAN]") -> 21 | I13: Jumlah penyelia yang bertanggungjawab terhadap pemantauan dan penyelarasan di peringkat daerah. | J13: PPPAK: Rumusan Pengisian, lajur Pengisian. | K13: =IF(ISNUMBER('Skor Senario A'!D13),'Skor Senario A'!D13,"Belum sah (data HQ kurang)") -> 17 | L13: ='Skor Senario A'!H13 -> YA
A14: 2 | B14: Kemahiran | C14: Bilangan kelas | D14: =IF(ISNUMBER('Data 9 Negeri'!D88),'Data 9 Negeri'!D88,"[DATA BELUM DIKEMUKAKAN]") -> 158 | E14: =IF(ISNUMBER('Data 9 Negeri'!E88),'Data 9 Negeri'!E88,"[DATA BELUM DIKEMUKAKAN]") -> 230 | F14: =IF(ISNUMBER('Data 9 Negeri'!F88),'Data 9 Negeri'!F88,"[DATA BELUM DIKEMUKAKAN]") -> 201 | G14: =IF(ISNUMBER('Data 9 Negeri'!G88),'Data 9 Negeri'!G88,"[DATA BELUM DIKEMUKAKAN]") -> 190 | H14: =W_KEM -> 0.15 | I14: Jumlah kelas atau aktiviti kemahiran yang dilaksanakan. | J14: PKEM 2026: bilangan rekod kelas (sheet PREMIS). Sabah: 543 disahkan terus negeri (Sept 2026), menggantikan anggaran PKEM 230 bagi Sabah sahaja; Sarawak, Johor dan Perak kekal guna anggaran PKEM. | K14: =IF(ISNUMBER('Skor Senario A'!D14),'Skor Senario A'!D14,"Belum sah (data HQ kurang)") -> 108 | L14: ='Skor Senario A'!H14 -> YA
C15: Bilangan program / aktiviti | D15: =IF(ISNUMBER('Data 9 Negeri'!D89),'Data 9 Negeri'!D89,"[DATA BELUM DIKEMUKAKAN]") -> 125 | E15: =IF(ISNUMBER('Data 9 Negeri'!E89),'Data 9 Negeri'!E89,"[DATA BELUM DIKEMUKAKAN]") -> 230 | F15: =IF(ISNUMBER('Data 9 Negeri'!F89),'Data 9 Negeri'!F89,"[DATA BELUM DIKEMUKAKAN]") -> 278 | G15: =IF(ISNUMBER('Data 9 Negeri'!G89),'Data 9 Negeri'!G89,"[DATA BELUM DIKEMUKAKAN]") -> 159 | I15: Jumlah program kemahiran yang perlu dirancang, diselaras dan dipantau. | J15: Borang B4 diisi lengkap oleh Sarawak, Sabah, Johor (Sept 2026) dan Perak (kemas kini 23 Sept 2026, v1.3). | K15: =IF(ISNUMBER('Skor Senario A'!D15),'Skor Senario A'!D15,"Belum sah (data HQ kurang)") -> 112.4 | L15: ='Skor Senario A'!H15 -> YA
C16: Bilangan guru | D16: =IF(ISNUMBER('Data 9 Negeri'!D90),'Data 9 Negeri'!D90,"[DATA BELUM DIKEMUKAKAN]") -> 68 | E16: =IF(ISNUMBER('Data 9 Negeri'!E90),'Data 9 Negeri'!E90,"[DATA BELUM DIKEMUKAKAN]") -> 112 | F16: =IF(ISNUMBER('Data 9 Negeri'!F90),'Data 9 Negeri'!F90,"[DATA BELUM DIKEMUKAKAN]") -> 88 | G16: =IF(ISNUMBER('Data 9 Negeri'!G90),'Data 9 Negeri'!G90,"[DATA BELUM DIKEMUKAKAN]") -> 92 | I16: Jumlah tenaga pengajar yang terlibat dalam program kemahiran. | J16: PKEM 2026: bilangan PM kemahiran (sheet PM). | K16: =IF(ISNUMBER('Skor Senario A'!D16),'Skor Senario A'!D16,"Belum sah (data HQ kurang)") -> 60.2 | L16: ='Skor Senario A'!H16 -> YA
C17: Bilangan peserta | D17: =IF(ISNUMBER('Data 9 Negeri'!D91),'Data 9 Negeri'!D91,"[DATA BELUM DIKEMUKAKAN]") -> 2496 | E17: =IF(ISNUMBER('Data 9 Negeri'!E91),'Data 9 Negeri'!E91,"[DATA BELUM DIKEMUKAKAN]") -> 4081 | F17: =IF(ISNUMBER('Data 9 Negeri'!F91),'Data 9 Negeri'!F91,"[DATA BELUM DIKEMUKAKAN]") -> 2842 | G17: =IF(ISNUMBER('Data 9 Negeri'!G91),'Data 9 Negeri'!G91,"[DATA BELUM DIKEMUKAKAN]") -> 3261 | I17: Jumlah peserta yang mengikuti kelas atau program kemahiran. | J17: PKEM 2026: jumlah peserta (sheet PREMIS). Sebahagian kelas tiada angka peserta. | K17: =IF(ISNUMBER('Skor Senario A'!D17),'Skor Senario A'!D17,"Belum sah (data HQ kurang)") -> 1467.4 | L17: ='Skor Senario A'!H17 -> YA
A18: 3 | B18: Komuniti | C18: Bilangan kampung | D18: =IF(ISNUMBER('Data 9 Negeri'!D92),'Data 9 Negeri'!D92,"[DATA BELUM DIKEMUKAKAN]") -> 6906 | E18: =IF(ISNUMBER('Data 9 Negeri'!E92),IF('Data 9 Negeri'!$E$110="Lengkap",'Data 9 Negeri'!E92,"≥"&TEXT('Data 9 Negeri'!E92,"#,##0")),"[DATA BELUM DIKEMUKAKAN]") -> ≥2,558 | F18: =IF(ISNUMBER('Data 9 Negeri'!F92),'Data 9 Negeri'!F92,"[DATA BELUM DIKEMUKAKAN]") -> 631 | G18: =IF(ISNUMBER('Data 9 Negeri'!G92),'Data 9 Negeri'!G92,"[DATA BELUM DIKEMUKAKAN]") -> 1079 | H18: =W_KOM -> 0.15 | I18: Jumlah kampung atau lokaliti yang berada dalam liputan perkhidmatan KEMAS. | J18: ="L1 Profil Negeri (jumlah kampung / rumah panjang semua DUN). Sabah: "&IF('Data 9 Negeri'!$E$110="Lengkap","lengkap.","had bawah; Papar, Tenom, Sandakan, Lahad Datu dan kampung Semporna belum diisi (Borang bahagian B).") -> L1 Profil Negeri (jumlah kampung / rumah panjang semua DUN). Sabah: had bawah; Papar, Tenom, Sandakan, Lahad Datu dan kampung Semporna belum diisi (Borang bahagian B). | K18: =IF(ISNUMBER('Skor Senario A'!D18),'Skor Senario A'!D18,"Belum sah (data HQ kurang)") -> 1032.8 | L18: ='Skor Senario A'!H18 -> YA
C19: Bilangan populasi | D19: =IF(ISNUMBER('Data 9 Negeri'!D93),'Data 9 Negeri'!D93,"[DATA BELUM DIKEMUKAKAN]") -> 2509500 | E19: =IF(ISNUMBER('Data 9 Negeri'!E93),IF(AND(P_SUMBER<>"Nasional",'Data 9 Negeri'!$E$111<>"Lengkap"),"≥"&TEXT('Data 9 Negeri'!E93,"#,##0"),'Data 9 Negeri'!E93),"[DATA BELUM DIKEMUKAKAN]") -> 3592800 | F19: =IF(ISNUMBER('Data 9 Negeri'!F93),'Data 9 Negeri'!F93,"[DATA BELUM DIKEMUKAKAN]") -> 4100900 | G19: =IF(ISNUMBER('Data 9 Negeri'!G93),'Data 9 Negeri'!G93,"[DATA BELUM DIKEMUKAKAN]") -> 2540400 | I19: Jumlah penduduk yang menjadi kumpulan sasaran program pembangunan komuniti. | J19: =IF(P_SUMBER="Nasional","DOSM: anggaran penduduk semasa 2023, sumber yang sama untuk 9 negeri (suis Nasional).","L1 Profil Negeri: anggaran penduduk semua DUN (suis Data HQ). Sabah had bawah sehingga Borang bahagian B diisi.") -> DOSM: anggaran penduduk semasa 2023, sumber yang sama untuk 9 negeri (suis Nasional). | K19: =IF(ISNUMBER('Skor Senario A'!D19),'Skor Senario A'!D19,"Belum sah (data HQ kurang)") -> 2820500 | L19: ='Skor Senario A'!H19 -> YA
C20: Bilangan aktiviti / program | D20: =IF(ISNUMBER('Data 9 Negeri'!D94),'Data 9 Negeri'!D94,"[DATA BELUM DIKEMUKAKAN]") -> 382 | E20: =IF(ISNUMBER('Data 9 Negeri'!E94),'Data 9 Negeri'!E94,"[DATA BELUM DIKEMUKAKAN]") -> 219 | F20: =IF(ISNUMBER('Data 9 Negeri'!F94),'Data 9 Negeri'!F94,"[DATA BELUM DIKEMUKAKAN]") -> 217 | G20: =IF(ISNUMBER('Data 9 Negeri'!G94),'Data 9 Negeri'!G94,"[DATA BELUM DIKEMUKAKAN]") -> 175 | I20: Jumlah aktiviti dan program komuniti yang dilaksanakan dan perlu dipantau. (†) | J20: Borang B5 diisi lengkap oleh Sarawak, Sabah, Johor (Sept 2026) dan Perak (kemas kini 23 Sept 2026, v1.3). | K20: =IF(ISNUMBER('Skor Senario A'!D20),'Skor Senario A'!D20,"Belum sah (data HQ kurang)") -> 93 | L20: ='Skor Senario A'!H20 -> YA
C21: Bilangan peserta | D21: =IF(ISNUMBER('Data 9 Negeri'!D95),'Data 9 Negeri'!D95,"[DATA BELUM DIKEMUKAKAN]") -> 20010 | E21: =IF(ISNUMBER('Data 9 Negeri'!E95),'Data 9 Negeri'!E95,"[DATA BELUM DIKEMUKAKAN]") -> 4313 | F21: =IF(ISNUMBER('Data 9 Negeri'!F95),'Data 9 Negeri'!F95,"[DATA BELUM DIKEMUKAKAN]") -> 2546 | G21: =IF(ISNUMBER('Data 9 Negeri'!G95),'Data 9 Negeri'!G95,"[DATA BELUM DIKEMUKAKAN]") -> 8500 | I21: Jumlah peserta yang mengikuti aktiviti dan program komuniti. (†) | J21: Borang B6 diisi lengkap oleh Sarawak, Sabah, Johor (Sept 2026) dan Perak (v1.3). Belum diskor kerana garis asas HQ masih belum sah: hanya 2 negeri sederhana ada data. | K21: =IF(ISNUMBER('Skor Senario A'!D21),'Skor Senario A'!D21,"Belum sah (data HQ kurang)") -> Belum sah (data HQ kurang) | L21: ='Skor Senario A'!H21 -> TIDAK
A22: 4 | B22: Pengurusan | C22: Aset alih | D22: =IF(ISNUMBER('Data 9 Negeri'!D96),'Data 9 Negeri'!D96,"[DATA BELUM DIKEMUKAKAN]") -> 28630 | E22: =IF(ISNUMBER('Data 9 Negeri'!E96),'Data 9 Negeri'!E96,"[DATA BELUM DIKEMUKAKAN]") -> 36669 | F22: =IF(ISNUMBER('Data 9 Negeri'!F96),'Data 9 Negeri'!F96,"[DATA BELUM DIKEMUKAKAN]") -> [DATA BELUM DIKEMUKAKAN] | G22: =IF(ISNUMBER('Data 9 Negeri'!G96),'Data 9 Negeri'!G96,"[DATA BELUM DIKEMUKAKAN]") -> 30408 | H22: =W_PENG -> 0.5 | I22: Jumlah aset alih yang perlu diurus, direkod, diselenggara dan dipantau. | J22: Borang B7 diisi oleh Sarawak (28,630 item), Sabah (36,669 item = Harta Modal 1,747 + Aset Bernilai Rendah 34,922) dan Perak (30,408 item, v1.3); Johor belum. Garis asas HQ belum sah: Pahang sahaja. | K22: =IF(ISNUMBER('Skor Senario A'!D22),'Skor Senario A'!D22,"Belum sah (data HQ kurang)") -> Belum sah (data HQ kurang) | L22: ='Skor Senario A'!H22 -> TIDAK
C23: Aset tidak alih | D23: =IF(ISNUMBER('Data 9 Negeri'!D97),'Data 9 Negeri'!D97,"[DATA BELUM DIKEMUKAKAN]") -> [DATA BELUM DIKEMUKAKAN] | E23: =IF(ISNUMBER('Data 9 Negeri'!E97),'Data 9 Negeri'!E97,"[DATA BELUM DIKEMUKAKAN]") -> 1022 | F23: =IF(ISNUMBER('Data 9 Negeri'!F97),'Data 9 Negeri'!F97,"[DATA BELUM DIKEMUKAKAN]") -> 893 | G23: =IF(ISNUMBER('Data 9 Negeri'!G97),'Data 9 Negeri'!G97,"[DATA BELUM DIKEMUKAKAN]") -> 367 | I23: Jumlah premis, bangunan atau aset tidak alih di bawah tanggungjawab pengurusan. | J23: Borang B9 diisi oleh Sabah (1,022 = Milikan 245 + Tumpang 717 + Sewa 60), Johor (893) dan Perak (367, v1.3). Sarawak menyatakan "tiada jumlah negeri" (belum diisi). Garis asas HQ belum sah: Pahang dan Kelantan sahaja. | K23: =IF(ISNUMBER('Skor Senario A'!D23),'Skor Senario A'!D23,"Belum sah (data HQ kurang)") -> Belum sah (data HQ kurang) | L23: ='Skor Senario A'!H23 -> TIDAK
C24: Bajet (OE) | D24: =IF(ISNUMBER('Data 9 Negeri'!D98),'Data 9 Negeri'!D98,"[DATA BELUM DIKEMUKAKAN]") -> 6896060.2 | E24: =IF(ISNUMBER('Data 9 Negeri'!E98),'Data 9 Negeri'!E98,"[DATA BELUM DIKEMUKAKAN]") -> 76816482 | F24: =IF(ISNUMBER('Data 9 Negeri'!F98),'Data 9 Negeri'!F98,"[DATA BELUM DIKEMUKAKAN]") -> 101223814 | G24: =IF(ISNUMBER('Data 9 Negeri'!G98),'Data 9 Negeri'!G98,"[DATA BELUM DIKEMUKAKAN]") -> 87049719 | I24: Nilai dan skala peruntukan kewangan yang perlu diurus. | J24: Borang B10 diisi lengkap: Sarawak (RM6,896,060), Sabah (RM76,816,482), Johor (RM101,223,814) dan Perak (RM87,049,719, v1.3). Belum diskor kerana garis asas HQ belum sah: Pahang dan Kelantan sahaja. | K24: =IF(ISNUMBER('Skor Senario A'!D24),'Skor Senario A'!D24,"Belum sah (data HQ kurang)") -> Belum sah (data HQ kurang) | L24: ='Skor Senario A'!H24 -> TIDAK
C25: Bajet (DE) | D25: =IF(ISNUMBER('Data 9 Negeri'!D99),'Data 9 Negeri'!D99,"[DATA BELUM DIKEMUKAKAN]") -> 8351734.2 | E25: =IF(ISNUMBER('Data 9 Negeri'!E99),'Data 9 Negeri'!E99,"[DATA BELUM DIKEMUKAKAN]") -> 7031639 | F25: =IF(ISNUMBER('Data 9 Negeri'!F99),'Data 9 Negeri'!F99,"[DATA BELUM DIKEMUKAKAN]") -> 3911500 | G25: =IF(ISNUMBER('Data 9 Negeri'!G99),'Data 9 Negeri'!G99,"[DATA BELUM DIKEMUKAKAN]") -> 3038000 | I25: Nilai dan skala peruntukan pembangunan (DE) yang perlu diurus. (†) | J25: Borang B11 diisi lengkap: Sarawak (RM8,351,734), Sabah (RM7,031,639), Johor (RM3,911,500) dan Perak (RM3,038,000, v1.3). Belum diskor kerana garis asas HQ belum sah: Pahang dan Kelantan sahaja. | K25: =IF(ISNUMBER('Skor Senario A'!D25),'Skor Senario A'!D25,"Belum sah (data HQ kurang)") -> Belum sah (data HQ kurang) | L25: ='Skor Senario A'!H25 -> TIDAK
C26: Bilangan Baucer | D26: =IF(ISNUMBER('Data 9 Negeri'!D100),'Data 9 Negeri'!D100,"[DATA BELUM DIKEMUKAKAN]") -> 15000 | E26: =IF(ISNUMBER('Data 9 Negeri'!E100),'Data 9 Negeri'!E100,"[DATA BELUM DIKEMUKAKAN]") -> 3997 | F26: =IF(ISNUMBER('Data 9 Negeri'!F100),'Data 9 Negeri'!F100,"[DATA BELUM DIKEMUKAKAN]") -> 4825 | G26: =IF(ISNUMBER('Data 9 Negeri'!G100),'Data 9 Negeri'!G100,"[DATA BELUM DIKEMUKAKAN]") -> 7500 | I26: Mengukur kekerapan dan kompleksiti proses agihan serta pemantauan peruntukan ke daerah. | J26: Borang B12 diisi lengkap: Sarawak (15,000; v1.3, menggantikan julat "10-15K" yang dihantar sebelum ini), Sabah (3,997), Johor (4,825) dan Perak (7,500, v1.3). Belum diskor kerana garis asas HQ belum sah: Pahang sahaja. | K26: =IF(ISNUMBER('Skor Senario A'!D26),'Skor Senario A'!D26,"Belum sah (data HQ kurang)") -> Belum sah (data HQ kurang) | L26: ='Skor Senario A'!H26 -> TIDAK
C27: Bilangan projek dan program | D27: =IF(ISNUMBER('Data 9 Negeri'!D101),'Data 9 Negeri'!D101,"[DATA BELUM DIKEMUKAKAN]") -> 507 | E27: =IF(ISNUMBER('Data 9 Negeri'!E101),'Data 9 Negeri'!E101,"[DATA BELUM DIKEMUKAKAN]") -> 204 | F27: =IF(ISNUMBER('Data 9 Negeri'!F101),'Data 9 Negeri'!F101,"[DATA BELUM DIKEMUKAKAN]") -> 46 | G27: =IF(ISNUMBER('Data 9 Negeri'!G101),'Data 9 Negeri'!G101,"[DATA BELUM DIKEMUKAKAN]") -> 450 | I27: Jumlah projek dan program yang memerlukan penyelarasan, pemantauan dan pelaporan. | J27: Borang B14 diisi lengkap: Sarawak (507), Sabah (204), Johor (46) dan Perak (450, v1.3). Johor hantar "46 Projek, 657 PO"; hanya 46 (Projek) digunakan kerana takrif "PO" belum disahkan. | K27: =IF(ISNUMBER('Skor Senario A'!D27),'Skor Senario A'!D27,"Belum sah (data HQ kurang)") -> 200.4 | L27: ='Skor Senario A'!H27 -> YA
C28: Perjawatan / pengurusan pegawai | D28: =IF(ISNUMBER('Data 9 Negeri'!D102),'Data 9 Negeri'!D102,"[DATA BELUM DIKEMUKAKAN]") -> 2032 | E28: =IF(ISNUMBER('Data 9 Negeri'!E102),IF(ISNUMBER('Borang Negeri'!H28),'Data 9 Negeri'!E102,TEXT('Data 9 Negeri'!E102,"#,##0")&"*"),"[DATA BELUM DIKEMUKAKAN]") -> 2,146* | F28: =IF(ISNUMBER('Data 9 Negeri'!F102),IF(ISNUMBER('Borang Negeri'!I28),'Data 9 Negeri'!F102,TEXT('Data 9 Negeri'!F102,"#,##0")&"*"),"[DATA BELUM DIKEMUKAKAN]") -> 1,508* | G28: =IF(ISNUMBER('Data 9 Negeri'!G102),'Data 9 Negeri'!G102,"[DATA BELUM DIKEMUKAKAN]") -> 1223 | I28: Jumlah pegawai dan kompleksiti urusan sumber manusia, pentadbiran dan penyeliaan. | J28: L3/L4 negeri (Kertas Cadangan v2.3): Sarawak dan Perak L3; Johor dan Sabah anggaran L4 (*), Sabah belum disahkan. Pengesahan melalui Borang B15. | K28: =IF(ISNUMBER('Skor Senario A'!D28),'Skor Senario A'!D28,"Belum sah (data HQ kurang)") -> 1179.4 | L28: ='Skor Senario A'!H28 -> YA
A29: JUMLAH KESELURUHAN | H29: =SUM(H6:H28) -> 1
A31: PETUNJUK MEMBACA MATRIKS
A32: Bil. | B32: Contoh paparan | D32: Maksud
A33: 1 | B33: [DATA BELUM DIKEMUKAKAN] | D33: Negeri belum mengemukakan data ikut takrif HQ; diminta melalui sheet Borang Negeri. Model dikira semula secara automatik apabila borang diisi.
A34: 2 | B34: ≥2,558 | D34: Had bawah: data negeri belum lengkap (contoh kampung Sabah, 4 daerah dan kampung Semporna belum diisi dalam L1).
A35: 3 | B35: 2,146* | D35: Anggaran L4 yang belum disahkan (perjawatan Sabah dan Johor); pengesahan melalui Borang B15.
A36: 4 | B36: YA / TIDAK | D36: Lajur Diskor?: YA = sub-kriteria dimasukkan dalam skor; TIDAK = data belum cukup (lihat sheet Skor Senario A).
A37: 5 | B37: Penerangan (†) | D37: Teks penerangan dibetulkan atau dilengkapkan daripada fail HQ (teks asal tersalin atau kosong); lihat Kaedah & Sumber bahagian 6.
A38: 6 | B38: Suis sumber | D38: Nilai negeri besar mengikut suis Sumber garis asas di sheet Ringkasan (kesan pada baris populasi sahaja; baris lain guna sumber yang sama dalam kedua-dua suis).

Sheet Skor Senario A
A1: SKOR SENARIO A: WAJARAN ASAL HQ (PAKK 20%, KEMAHIRAN 15%, KOMUNITI 15%, PENGURUSAN 50%)
A2: ="Nisbah = nilai negeri / purata 5 negeri sederhana | Sumber garis asas: "&P_SUMBER&" | Had nisbah: "&IF(P_HAD>=99,"tiada",TEXT(P_HAD,"0.0"))&" | Garis asas sah jika sekurang-kurangnya "&P_MINN&" negeri sederhana ada data" -> Nisbah = nilai negeri / purata 5 negeri sederhana | Sumber garis asas: Nasional | Had nisbah: tiada | Garis asas sah jika sekurang-kurangnya 3 negeri sederhana ada data
A4: SUB-KRITERIA, GARIS ASAS DAN KELAYAKAN | I4: NISBAH NEGERI BESAR | M4: NISBAH NEGERI SEDERHANA (rujukan) | R4: SEMAKAN
A5: Kod | B5: Kriteria | C5: Sub kriteria | D5: Garis asas (purata sederhana) | E5: n sederhana | F5: n besar | G5: Paksa (pilihan: YA / TIDAK) | H5: Masuk skor? | I5: Sarawak | J5: Sabah | K5: Johor | L5: Perak | M5: Selangor | N5: Kedah | O5: Pahang | P5: Terengganu | Q5: Kelantan | R5: Purata nisbah sederhana | S5: Purata nisbah besar
A6: 1.1 | B6: Pendidikan Awal Kanak-Kanak | C6: Bilangan kelas TABIKA | D6: =IF(E6>=P_MINN,AVERAGE('Data 9 Negeri'!H80:L80),"") -> 860.6 | E6: =COUNT('Data 9 Negeri'!H80:L80) -> 5 | F6: =COUNT('Data 9 Negeri'!D80:G80) -> 4 | H6: =IF(G6<>"",UPPER(TRIM(G6)),IF(AND(E6>=P_MINN,F6=4),"YA","TIDAK")) -> YA | I6: =IF(AND($H6="YA",ISNUMBER($D6),ISNUMBER('Data 9 Negeri'!D80)),IFERROR(MIN('Data 9 Negeri'!D80/$D6,P_HAD),""),"") -> 1.510574 | J6: =IF(AND($H6="YA",ISNUMBER($D6),ISNUMBER('Data 9 Negeri'!E80)),IFERROR(MIN('Data 9 Negeri'!E80/$D6,P_HAD),""),"") -> 1.629096 | K6: =IF(AND($H6="YA",ISNUMBER($D6),ISNUMBER('Data 9 Negeri'!F80)),IFERROR(MIN('Data 9 Negeri'!F80/$D6,P_HAD),""),"") -> 1.3502208 | L6: =IF(AND($H6="YA",ISNUMBER($D6),ISNUMBER('Data 9 Negeri'!G80)),IFERROR(MIN('Data 9 Negeri'!G80/$D6,P_HAD),""),"") -> 0.93423193 | M6: =IF(AND($H6="YA",ISNUMBER($D6),ISNUMBER('Data 9 Negeri'!H80)),IFERROR(MIN('Data 9 Negeri'!H80/$D6,P_HAD),""),"") -> 1.218917 | N6: =IF(AND($H6="YA",ISNUMBER($D6),ISNUMBER('Data 9 Negeri'!I80)),IFERROR(MIN('Data 9 Negeri'!I80/$D6,P_HAD),""),"") -> 0.93306995 | O6: =IF(AND($H6="YA",ISNUMBER($D6),ISNUMBER('Data 9 Negeri'!J80)),IFERROR(MIN('Data 9 Negeri'!J80/$D6,P_HAD),""),"") -> 1.0213804 | P6: =IF(AND($H6="YA",ISNUMBER($D6),ISNUMBER('Data 9 Negeri'!K80)),IFERROR(MIN('Data 9 Negeri'!K80/$D6,P_HAD),""),"") -> 0.97490123 | Q6: =IF(AND($H6="YA",ISNUMBER($D6),ISNUMBER('Data 9 Negeri'!L80)),IFERROR(MIN('Data 9 Negeri'!L80/$D6,P_HAD),""),"") -> 0.85173135 | R6: =IFERROR(AVERAGE(M6:Q6),"") -> 1 | S6: =IFERROR(AVERAGE(I6:L6),"") -> 1.3560307
A7: 1.2 | B7: Pendidikan Awal Kanak-Kanak | C7: Bilangan kelas TASKA | D7: =IF(E7>=P_MINN,AVERAGE('Data 9 Negeri'!H81:L81),"") -> 39.6 | E7: =COUNT('Data 9 Negeri'!H81:L81) -> 5 | F7: =COUNT('Data 9 Negeri'!D81:G81) -> 4 | H7: =IF(G7<>"",UPPER(TRIM(G7)),IF(AND(E7>=P_MINN,F7=4),"YA","TIDAK")) -> YA | I7: =IF(AND($H7="YA",ISNUMBER($D7),ISNUMBER('Data 9 Negeri'!D81)),IFERROR(MIN('Data 9 Negeri'!D81/$D7,P_HAD),""),"") -> 2.1464646 | J7: =IF(AND($H7="YA",ISNUMBER($D7),ISNUMBER('Data 9 Negeri'!E81)),IFERROR(MIN('Data 9 Negeri'!E81/$D7,P_HAD),""),"") -> 1.6919192 | K7: =IF(AND($H7="YA",ISNUMBER($D7),ISNUMBER('Data 9 Negeri'!F81)),IFERROR(MIN('Data 9 Negeri'!F81/$D7,P_HAD),""),"") -> 1.489899 | L7: =IF(AND($H7="YA",ISNUMBER($D7),ISNUMBER('Data 9 Negeri'!G81)),IFERROR(MIN('Data 9 Negeri'!G81/$D7,P_HAD),""),"") -> 1.1111111 | M7: =IF(AND($H7="YA",ISNUMBER($D7),ISNUMBER('Data 9 Negeri'!H81)),IFERROR(MIN('Data 9 Negeri'!H81/$D7,P_HAD),""),"") -> 0.95959596 | N7: =IF(AND($H7="YA",ISNUMBER($D7),ISNUMBER('Data 9 Negeri'!I81)),IFERROR(MIN('Data 9 Negeri'!I81/$D7,P_HAD),""),"") -> 1.4141414 | O7: =IF(AND($H7="YA",ISNUMBER($D7),ISNUMBER('Data 9 Negeri'!J81)),IFERROR(MIN('Data 9 Negeri'!J81/$D7,P_HAD),""),"") -> 0.90909091 | P7: =IF(AND($H7="YA",ISNUMBER($D7),ISNUMBER('Data 9 Negeri'!K81)),IFERROR(MIN('Data 9 Negeri'!K81/$D7,P_HAD),""),"") -> 0.78282828 | Q7: =IF(AND($H7="YA",ISNUMBER($D7),ISNUMBER('Data 9 Negeri'!L81)),IFERROR(MIN('Data 9 Negeri'!L81/$D7,P_HAD),""),"") -> 0.93434343 | R7: =IFERROR(AVERAGE(M7:Q7),"") -> 1 | S7: =IFERROR(AVERAGE(I7:L7),"") -> 1.6098485
A8: 1.3 | B8: Pendidikan Awal Kanak-Kanak | C8: Bilangan guru TABIKA | D8: =IF(E8>=P_MINN,AVERAGE('Data 9 Negeri'!H82:L82),"") -> 819 | E8: =COUNT('Data 9 Negeri'!H82:L82) -> 5 | F8: =COUNT('Data 9 Negeri'!D82:G82) -> 4 | H8: =IF(G8<>"",UPPER(TRIM(G8)),IF(AND(E8>=P_MINN,F8=4),"YA","TIDAK")) -> YA | I8: =IF(AND($H8="YA",ISNUMBER($D8),ISNUMBER('Data 9 Negeri'!D82)),IFERROR(MIN('Data 9 Negeri'!D82/$D8,P_HAD),""),"") -> 1.5763126 | J8: =IF(AND($H8="YA",ISNUMBER($D8),ISNUMBER('Data 9 Negeri'!E82)),IFERROR(MIN('Data 9 Negeri'!E82/$D8,P_HAD),""),"") -> 1.6471306 | K8: =IF(AND($H8="YA",ISNUMBER($D8),ISNUMBER('Data 9 Negeri'!F82)),IFERROR(MIN('Data 9 Negeri'!F82/$D8,P_HAD),""),"") -> 1.2735043 | L8: =IF(AND($H8="YA",ISNUMBER($D8),ISNUMBER('Data 9 Negeri'!G82)),IFERROR(MIN('Data 9 Negeri'!G82/$D8,P_HAD),""),"") -> 0.92429792 | M8: =IF(AND($H8="YA",ISNUMBER($D8),ISNUMBER('Data 9 Negeri'!H82)),IFERROR(MIN('Data 9 Negeri'!H82/$D8,P_HAD),""),"") -> 1.1562882 | N8: =IF(AND($H8="YA",ISNUMBER($D8),ISNUMBER('Data 9 Negeri'!I82)),IFERROR(MIN('Data 9 Negeri'!I82/$D8,P_HAD),""),"") -> 0.92307692 | O8: =IF(AND($H8="YA",ISNUMBER($D8),ISNUMBER('Data 9 Negeri'!J82)),IFERROR(MIN('Data 9 Negeri'!J82/$D8,P_HAD),""),"") -> 1.018315 | P8: =IF(AND($H8="YA",ISNUMBER($D8),ISNUMBER('Data 9 Negeri'!K82)),IFERROR(MIN('Data 9 Negeri'!K82/$D8,P_HAD),""),"") -> 1.007326 | Q8: =IF(AND($H8="YA",ISNUMBER($D8),ISNUMBER('Data 9 Negeri'!L82)),IFERROR(MIN('Data 9 Negeri'!L82/$D8,P_HAD),""),"") -> 0.89499389 | R8: =IFERROR(AVERAGE(M8:Q8),"") -> 1 | S8: =IFERROR(AVERAGE(I8:L8),"") -> 1.3553114
A9: 1.4 | B9: Pendidikan Awal Kanak-Kanak | C9: Bilangan guru TASKA | D9: =IF(E9>=P_MINN,AVERAGE('Data 9 Negeri'!H83:L83),"") -> 140.2 | E9: =COUNT('Data 9 Negeri'!H83:L83) -> 5 | F9: =COUNT('Data 9 Negeri'!D83:G83) -> 4 | H9: =IF(G9<>"",UPPER(TRIM(G9)),IF(AND(E9>=P_MINN,F9=4),"YA","TIDAK")) -> YA | I9: =IF(AND($H9="YA",ISNUMBER($D9),ISNUMBER('Data 9 Negeri'!D83)),IFERROR(MIN('Data 9 Negeri'!D83/$D9,P_HAD),""),"") -> 1.7760342 | J9: =IF(AND($H9="YA",ISNUMBER($D9),ISNUMBER('Data 9 Negeri'!E83)),IFERROR(MIN('Data 9 Negeri'!E83/$D9,P_HAD),""),"") -> 1.4693295 | K9: =IF(AND($H9="YA",ISNUMBER($D9),ISNUMBER('Data 9 Negeri'!F83)),IFERROR(MIN('Data 9 Negeri'!F83/$D9,P_HAD),""),"") -> 1.2767475 | L9: =IF(AND($H9="YA",ISNUMBER($D9),ISNUMBER('Data 9 Negeri'!G83)),IFERROR(MIN('Data 9 Negeri'!G83/$D9,P_HAD),""),"") -> 1.0627675 | M9: =IF(AND($H9="YA",ISNUMBER($D9),ISNUMBER('Data 9 Negeri'!H83)),IFERROR(MIN('Data 9 Negeri'!H83/$D9,P_HAD),""),"") -> 1.1982882 | N9: =IF(AND($H9="YA",ISNUMBER($D9),ISNUMBER('Data 9 Negeri'!I83)),IFERROR(MIN('Data 9 Negeri'!I83/$D9,P_HAD),""),"") -> 1.4051355 | O9: =IF(AND($H9="YA",ISNUMBER($D9),ISNUMBER('Data 9 Negeri'!J83)),IFERROR(MIN('Data 9 Negeri'!J83/$D9,P_HAD),""),"") -> 0.83452211 | P9: =IF(AND($H9="YA",ISNUMBER($D9),ISNUMBER('Data 9 Negeri'!K83)),IFERROR(MIN('Data 9 Negeri'!K83/$D9,P_HAD),""),"") -> 0.74179743 | Q9: =IF(AND($H9="YA",ISNUMBER($D9),ISNUMBER('Data 9 Negeri'!L83)),IFERROR(MIN('Data 9 Negeri'!L83/$D9,P_HAD),""),"") -> 0.82025678 | R9: =IFERROR(AVERAGE(M9:Q9),"") -> 1 | S9: =IFERROR(AVERAGE(I9:L9),"") -> 1.3962197
A10: 1.5 | B10: Pendidikan Awal Kanak-Kanak | C10: Bilangan pembantu | D10: =IF(E10>=P_MINN,AVERAGE('Data 9 Negeri'!H84:L84),"") -> 892.6 | E10: =COUNT('Data 9 Negeri'!H84:L84) -> 5 | F10: =COUNT('Data 9 Negeri'!D84:G84) -> 4 | H10: =IF(G10<>"",UPPER(TRIM(G10)),IF(AND(E10>=P_MINN,F10=4),"YA","TIDAK")) -> YA | I10: =IF(AND($H10="YA",ISNUMBER($D10),ISNUMBER('Data 9 Negeri'!D84)),IFERROR(MIN('Data 9 Negeri'!D84/$D10,P_HAD),""),"") -> 1.4149675 | J10: =IF(AND($H10="YA",ISNUMBER($D10),ISNUMBER('Data 9 Negeri'!E84)),IFERROR(MIN('Data 9 Negeri'!E84/$D10,P_HAD),""),"") -> 1.6412727 | K10: =IF(AND($H10="YA",ISNUMBER($D10),ISNUMBER('Data 9 Negeri'!F84)),IFERROR(MIN('Data 9 Negeri'!F84/$D10,P_HAD),""),"") -> 1.3701546 | L10: =IF(AND($H10="YA",ISNUMBER($D10),ISNUMBER('Data 9 Negeri'!G84)),IFERROR(MIN('Data 9 Negeri'!G84/$D10,P_HAD),""),"") -> 0.95115393 | M10: =IF(AND($H10="YA",ISNUMBER($D10),ISNUMBER('Data 9 Negeri'!H84)),IFERROR(MIN('Data 9 Negeri'!H84/$D10,P_HAD),""),"") -> 1.2110688 | N10: =IF(AND($H10="YA",ISNUMBER($D10),ISNUMBER('Data 9 Negeri'!I84)),IFERROR(MIN('Data 9 Negeri'!I84/$D10,P_HAD),""),"") -> 0.96347748 | O10: =IF(AND($H10="YA",ISNUMBER($D10),ISNUMBER('Data 9 Negeri'!J84)),IFERROR(MIN('Data 9 Negeri'!J84/$D10,P_HAD),""),"") -> 1.0239749 | P10: =IF(AND($H10="YA",ISNUMBER($D10),ISNUMBER('Data 9 Negeri'!K84)),IFERROR(MIN('Data 9 Negeri'!K84/$D10,P_HAD),""),"") -> 0.93771006 | Q10: =IF(AND($H10="YA",ISNUMBER($D10),ISNUMBER('Data 9 Negeri'!L84)),IFERROR(MIN('Data 9 Negeri'!L84/$D10,P_HAD),""),"") -> 0.86376877 | R10: =IFERROR(AVERAGE(M10:Q10),"") -> 1 | S10: =IFERROR(AVERAGE(I10:L10),"") -> 1.3443872
A11: 1.6 | B11: Pendidikan Awal Kanak-Kanak | C11: Bilangan murid TABIKA | D11: =IF(E11>=P_MINN,AVERAGE('Data 9 Negeri'!H85:L85),"") -> 18423.4 | E11: =COUNT('Data 9 Negeri'!H85:L85) -> 5 | F11: =COUNT('Data 9 Negeri'!D85:G85) -> 4 | H11: =IF(G11<>"",UPPER(TRIM(G11)),IF(AND(E11>=P_MINN,F11=4),"YA","TIDAK")) -> YA | I11: =IF(AND($H11="YA",ISNUMBER($D11),ISNUMBER('Data 9 Negeri'!D85)),IFERROR(MIN('Data 9 Negeri'!D85/$D11,P_HAD),""),"") -> 0.88165051 | J11: =IF(AND($H11="YA",ISNUMBER($D11),ISNUMBER('Data 9 Negeri'!E85)),IFERROR(MIN('Data 9 Negeri'!E85/$D11,P_HAD),""),"") -> 1.4227016 | K11: =IF(AND($H11="YA",ISNUMBER($D11),ISNUMBER('Data 9 Negeri'!F85)),IFERROR(MIN('Data 9 Negeri'!F85/$D11,P_HAD),""),"") -> 1.3018227 | L11: =IF(AND($H11="YA",ISNUMBER($D11),ISNUMBER('Data 9 Negeri'!G85)),IFERROR(MIN('Data 9 Negeri'!G85/$D11,P_HAD),""),"") -> 0.82563479 | M11: =IF(AND($H11="YA",ISNUMBER($D11),ISNUMBER('Data 9 Negeri'!H85)),IFERROR(MIN('Data 9 Negeri'!H85/$D11,P_HAD),""),"") -> 1.3946937 | N11: =IF(AND($H11="YA",ISNUMBER($D11),ISNUMBER('Data 9 Negeri'!I85)),IFERROR(MIN('Data 9 Negeri'!I85/$D11,P_HAD),""),"") -> 0.91155813 | O11: =IF(AND($H11="YA",ISNUMBER($D11),ISNUMBER('Data 9 Negeri'!J85)),IFERROR(MIN('Data 9 Negeri'!J85/$D11,P_HAD),""),"") -> 0.84930035 | P11: =IF(AND($H11="YA",ISNUMBER($D11),ISNUMBER('Data 9 Negeri'!K85)),IFERROR(MIN('Data 9 Negeri'!K85/$D11,P_HAD),""),"") -> 0.99102229 | Q11: =IF(AND($H11="YA",ISNUMBER($D11),ISNUMBER('Data 9 Negeri'!L85)),IFERROR(MIN('Data 9 Negeri'!L85/$D11,P_HAD),""),"") -> 0.85342553 | R11: =IFERROR(AVERAGE(M11:Q11),"") -> 1 | S11: =IFERROR(AVERAGE(I11:L11),"") -> 1.1079524
A12: 1.7 | B12: Pendidikan Awal Kanak-Kanak | C12: Bilangan murid TASKA | D12: =IF(E12>=P_MINN,AVERAGE('Data 9 Negeri'!H86:L86),"") -> 795.8 | E12: =COUNT('Data 9 Negeri'!H86:L86) -> 5 | F12: =COUNT('Data 9 Negeri'!D86:G86) -> 4 | H12: =IF(G12<>"",UPPER(TRIM(G12)),IF(AND(E12>=P_MINN,F12=4),"YA","TIDAK")) -> YA | I12: =IF(AND($H12="YA",ISNUMBER($D12),ISNUMBER('Data 9 Negeri'!D86)),IFERROR(MIN('Data 9 Negeri'!D86/$D12,P_HAD),""),"") -> 1.5192259 | J12: =IF(AND($H12="YA",ISNUMBER($D12),ISNUMBER('Data 9 Negeri'!E86)),IFERROR(MIN('Data 9 Negeri'!E86/$D12,P_HAD),""),"") -> 1.7554662 | K12: =IF(AND($H12="YA",ISNUMBER($D12),ISNUMBER('Data 9 Negeri'!F86)),IFERROR(MIN('Data 9 Negeri'!F86/$D12,P_HAD),""),"") -> 1.3872832 | L12: =IF(AND($H12="YA",ISNUMBER($D12),ISNUMBER('Data 9 Negeri'!G86)),IFERROR(MIN('Data 9 Negeri'!G86/$D12,P_HAD),""),"") -> 1.1032923 | M12: =IF(AND($H12="YA",ISNUMBER($D12),ISNUMBER('Data 9 Negeri'!H86)),IFERROR(MIN('Data 9 Negeri'!H86/$D12,P_HAD),""),"") -> 1.0103041 | N12: =IF(AND($H12="YA",ISNUMBER($D12),ISNUMBER('Data 9 Negeri'!I86)),IFERROR(MIN('Data 9 Negeri'!I86/$D12,P_HAD),""),"") -> 1.4425735 | O12: =IF(AND($H12="YA",ISNUMBER($D12),ISNUMBER('Data 9 Negeri'!J86)),IFERROR(MIN('Data 9 Negeri'!J86/$D12,P_HAD),""),"") -> 0.89972355 | P12: =IF(AND($H12="YA",ISNUMBER($D12),ISNUMBER('Data 9 Negeri'!K86)),IFERROR(MIN('Data 9 Negeri'!K86/$D12,P_HAD),""),"") -> 0.7464187 | Q12: =IF(AND($H12="YA",ISNUMBER($D12),ISNUMBER('Data 9 Negeri'!L86)),IFERROR(MIN('Data 9 Negeri'!L86/$D12,P_HAD),""),"") -> 0.90098015 | R12: =IFERROR(AVERAGE(M12:Q12),"") -> 1 | S12: =IFERROR(AVERAGE(I12:L12),"") -> 1.4413169
A13: 1.8 | B13: Pendidikan Awal Kanak-Kanak | C13: Bilangan penyelia daerah | D13: =IF(E13>=P_MINN,AVERAGE('Data 9 Negeri'!H87:L87),"") -> 17 | E13: =COUNT('Data 9 Negeri'!H87:L87) -> 5 | F13: =COUNT('Data 9 Negeri'!D87:G87) -> 4 | H13: =IF(G13<>"",UPPER(TRIM(G13)),IF(AND(E13>=P_MINN,F13=4),"YA","TIDAK")) -> YA | I13: =IF(AND($H13="YA",ISNUMBER($D13),ISNUMBER('Data 9 Negeri'!D87)),IFERROR(MIN('Data 9 Negeri'!D87/$D13,P_HAD),""),"") -> 2.1764706 | J13: =IF(AND($H13="YA",ISNUMBER($D13),ISNUMBER('Data 9 Negeri'!E87)),IFERROR(MIN('Data 9 Negeri'!E87/$D13,P_HAD),""),"") -> 2.1176471 | K13: =IF(AND($H13="YA",ISNUMBER($D13),ISNUMBER('Data 9 Negeri'!F87)),IFERROR(MIN('Data 9 Negeri'!F87/$D13,P_HAD),""),"") -> 1.1764706 | L13: =IF(AND($H13="YA",ISNUMBER($D13),ISNUMBER('Data 9 Negeri'!G87)),IFERROR(MIN('Data 9 Negeri'!G87/$D13,P_HAD),""),"") -> 1.2352941 | M13: =IF(AND($H13="YA",ISNUMBER($D13),ISNUMBER('Data 9 Negeri'!H87)),IFERROR(MIN('Data 9 Negeri'!H87/$D13,P_HAD),""),"") -> 1.0588235 | N13: =IF(AND($H13="YA",ISNUMBER($D13),ISNUMBER('Data 9 Negeri'!I87)),IFERROR(MIN('Data 9 Negeri'!I87/$D13,P_HAD),""),"") -> 0.88235294 | O13: =IF(AND($H13="YA",ISNUMBER($D13),ISNUMBER('Data 9 Negeri'!J87)),IFERROR(MIN('Data 9 Negeri'!J87/$D13,P_HAD),""),"") -> 1.1176471 | P13: =IF(AND($H13="YA",ISNUMBER($D13),ISNUMBER('Data 9 Negeri'!K87)),IFERROR(MIN('Data 9 Negeri'!K87/$D13,P_HAD),""),"") -> 0.94117647 | Q13: =IF(AND($H13="YA",ISNUMBER($D13),ISNUMBER('Data 9 Negeri'!L87)),IFERROR(MIN('Data 9 Negeri'!L87/$D13,P_HAD),""),"") -> 1 | R13: =IFERROR(AVERAGE(M13:Q13),"") -> 1 | S13: =IFERROR(AVERAGE(I13:L13),"") -> 1.6764706
A14: 2.1 | B14: Kemahiran | C14: Bilangan kelas | D14: =IF(E14>=P_MINN,AVERAGE('Data 9 Negeri'!H88:L88),"") -> 108 | E14: =COUNT('Data 9 Negeri'!H88:L88) -> 5 | F14: =COUNT('Data 9 Negeri'!D88:G88) -> 4 | H14: =IF(G14<>"",UPPER(TRIM(G14)),IF(AND(E14>=P_MINN,F14=4),"YA","TIDAK")) -> YA | I14: =IF(AND($H14="YA",ISNUMBER($D14),ISNUMBER('Data 9 Negeri'!D88)),IFERROR(MIN('Data 9 Negeri'!D88/$D14,P_HAD),""),"") -> 1.462963 | J14: =IF(AND($H14="YA",ISNUMBER($D14),ISNUMBER('Data 9 Negeri'!E88)),IFERROR(MIN('Data 9 Negeri'!E88/$D14,P_HAD),""),"") -> 2.1296296 | K14: =IF(AND($H14="YA",ISNUMBER($D14),ISNUMBER('Data 9 Negeri'!F88)),IFERROR(MIN('Data 9 Negeri'!F88/$D14,P_HAD),""),"") -> 1.8611111 | L14: =IF(AND($H14="YA",ISNUMBER($D14),ISNUMBER('Data 9 Negeri'!G88)),IFERROR(MIN('Data 9 Negeri'!G88/$D14,P_HAD),""),"") -> 1.7592593 | M14: =IF(AND($H14="YA",ISNUMBER($D14),ISNUMBER('Data 9 Negeri'!H88)),IFERROR(MIN('Data 9 Negeri'!H88/$D14,P_HAD),""),"") -> 1.1111111 | N14: =IF(AND($H14="YA",ISNUMBER($D14),ISNUMBER('Data 9 Negeri'!I88)),IFERROR(MIN('Data 9 Negeri'!I88/$D14,P_HAD),""),"") -> 0.58333333 | O14: =IF(AND($H14="YA",ISNUMBER($D14),ISNUMBER('Data 9 Negeri'!J88)),IFERROR(MIN('Data 9 Negeri'!J88/$D14,P_HAD),""),"") -> 1.4351852 | P14: =IF(AND($H14="YA",ISNUMBER($D14),ISNUMBER('Data 9 Negeri'!K88)),IFERROR(MIN('Data 9 Negeri'!K88/$D14,P_HAD),""),"") -> 0.84259259 | Q14: =IF(AND($H14="YA",ISNUMBER($D14),ISNUMBER('Data 9 Negeri'!L88)),IFERROR(MIN('Data 9 Negeri'!L88/$D14,P_HAD),""),"") -> 1.0277778 | R14: =IFERROR(AVERAGE(M14:Q14),"") -> 1 | S14: =IFERROR(AVERAGE(I14:L14),"") -> 1.8032407
A15: 2.2 | B15: Kemahiran | C15: Bilangan program / aktiviti | D15: =IF(E15>=P_MINN,AVERAGE('Data 9 Negeri'!H89:L89),"") -> 112.4 | E15: =COUNT('Data 9 Negeri'!H89:L89) -> 5 | F15: =COUNT('Data 9 Negeri'!D89:G89) -> 4 | H15: =IF(G15<>"",UPPER(TRIM(G15)),IF(AND(E15>=P_MINN,F15=4),"YA","TIDAK")) -> YA | I15: =IF(AND($H15="YA",ISNUMBER($D15),ISNUMBER('Data 9 Negeri'!D89)),IFERROR(MIN('Data 9 Negeri'!D89/$D15,P_HAD),""),"") -> 1.1120996 | J15: =IF(AND($H15="YA",ISNUMBER($D15),ISNUMBER('Data 9 Negeri'!E89)),IFERROR(MIN('Data 9 Negeri'!E89/$D15,P_HAD),""),"") -> 2.0462633 | K15: =IF(AND($H15="YA",ISNUMBER($D15),ISNUMBER('Data 9 Negeri'!F89)),IFERROR(MIN('Data 9 Negeri'!F89/$D15,P_HAD),""),"") -> 2.4733096 | L15: =IF(AND($H15="YA",ISNUMBER($D15),ISNUMBER('Data 9 Negeri'!G89)),IFERROR(MIN('Data 9 Negeri'!G89/$D15,P_HAD),""),"") -> 1.4145907 | M15: =IF(AND($H15="YA",ISNUMBER($D15),ISNUMBER('Data 9 Negeri'!H89)),IFERROR(MIN('Data 9 Negeri'!H89/$D15,P_HAD),""),"") -> 1.4679715 | N15: =IF(AND($H15="YA",ISNUMBER($D15),ISNUMBER('Data 9 Negeri'!I89)),IFERROR(MIN('Data 9 Negeri'!I89/$D15,P_HAD),""),"") -> 0.46263345 | O15: =IF(AND($H15="YA",ISNUMBER($D15),ISNUMBER('Data 9 Negeri'!J89)),IFERROR(MIN('Data 9 Negeri'!J89/$D15,P_HAD),""),"") -> 1.4501779 | P15: =IF(AND($H15="YA",ISNUMBER($D15),ISNUMBER('Data 9 Negeri'!K89)),IFERROR(MIN('Data 9 Negeri'!K89/$D15,P_HAD),""),"") -> 0.72953737 | Q15: =IF(AND($H15="YA",ISNUMBER($D15),ISNUMBER('Data 9 Negeri'!L89)),IFERROR(MIN('Data 9 Negeri'!L89/$D15,P_HAD),""),"") -> 0.88967972 | R15: =IFERROR(AVERAGE(M15:Q15),"") -> 1 | S15: =IFERROR(AVERAGE(I15:L15),"") -> 1.7615658
A16: 2.3 | B16: Kemahiran | C16: Bilangan guru | D16: =IF(E16>=P_MINN,AVERAGE('Data 9 Negeri'!H90:L90),"") -> 60.2 | E16: =COUNT('Data 9 Negeri'!H90:L90) -> 5 | F16: =COUNT('Data 9 Negeri'!D90:G90) -> 4 | H16: =IF(G16<>"",UPPER(TRIM(G16)),IF(AND(E16>=P_MINN,F16=4),"YA","TIDAK")) -> YA | I16: =IF(AND($H16="YA",ISNUMBER($D16),ISNUMBER('Data 9 Negeri'!D90)),IFERROR(MIN('Data 9 Negeri'!D90/$D16,P_HAD),""),"") -> 1.1295681 | J16: =IF(AND($H16="YA",ISNUMBER($D16),ISNUMBER('Data 9 Negeri'!E90)),IFERROR(MIN('Data 9 Negeri'!E90/$D16,P_HAD),""),"") -> 1.8604651 | K16: =IF(AND($H16="YA",ISNUMBER($D16),ISNUMBER('Data 9 Negeri'!F90)),IFERROR(MIN('Data 9 Negeri'!F90/$D16,P_HAD),""),"") -> 1.461794 | L16: =IF(AND($H16="YA",ISNUMBER($D16),ISNUMBER('Data 9 Negeri'!G90)),IFERROR(MIN('Data 9 Negeri'!G90/$D16,P_HAD),""),"") -> 1.5282392 | M16: =IF(AND($H16="YA",ISNUMBER($D16),ISNUMBER('Data 9 Negeri'!H90)),IFERROR(MIN('Data 9 Negeri'!H90/$D16,P_HAD),""),"") -> 1.0465116 | N16: =IF(AND($H16="YA",ISNUMBER($D16),ISNUMBER('Data 9 Negeri'!I90)),IFERROR(MIN('Data 9 Negeri'!I90/$D16,P_HAD),""),"") -> 0.98006645 | O16: =IF(AND($H16="YA",ISNUMBER($D16),ISNUMBER('Data 9 Negeri'!J90)),IFERROR(MIN('Data 9 Negeri'!J90/$D16,P_HAD),""),"") -> 1.0299003 | P16: =IF(AND($H16="YA",ISNUMBER($D16),ISNUMBER('Data 9 Negeri'!K90)),IFERROR(MIN('Data 9 Negeri'!K90/$D16,P_HAD),""),"") -> 0.98006645 | Q16: =IF(AND($H16="YA",ISNUMBER($D16),ISNUMBER('Data 9 Negeri'!L90)),IFERROR(MIN('Data 9 Negeri'!L90/$D16,P_HAD),""),"") -> 0.96345515 | R16: =IFERROR(AVERAGE(M16:Q16),"") -> 1 | S16: =IFERROR(AVERAGE(I16:L16),"") -> 1.4950166
A17: 2.4 | B17: Kemahiran | C17: Bilangan peserta | D17: =IF(E17>=P_MINN,AVERAGE('Data 9 Negeri'!H91:L91),"") -> 1467.4 | E17: =COUNT('Data 9 Negeri'!H91:L91) -> 5 | F17: =COUNT('Data 9 Negeri'!D91:G91) -> 4 | H17: =IF(G17<>"",UPPER(TRIM(G17)),IF(AND(E17>=P_MINN,F17=4),"YA","TIDAK")) -> YA | I17: =IF(AND($H17="YA",ISNUMBER($D17),ISNUMBER('Data 9 Negeri'!D91)),IFERROR(MIN('Data 9 Negeri'!D91/$D17,P_HAD),""),"") -> 1.7009677 | J17: =IF(AND($H17="YA",ISNUMBER($D17),ISNUMBER('Data 9 Negeri'!E91)),IFERROR(MIN('Data 9 Negeri'!E91/$D17,P_HAD),""),"") -> 2.7811094 | K17: =IF(AND($H17="YA",ISNUMBER($D17),ISNUMBER('Data 9 Negeri'!F91)),IFERROR(MIN('Data 9 Negeri'!F91/$D17,P_HAD),""),"") -> 1.9367589 | L17: =IF(AND($H17="YA",ISNUMBER($D17),ISNUMBER('Data 9 Negeri'!G91)),IFERROR(MIN('Data 9 Negeri'!G91/$D17,P_HAD),""),"") -> 2.2222979 | M17: =IF(AND($H17="YA",ISNUMBER($D17),ISNUMBER('Data 9 Negeri'!H91)),IFERROR(MIN('Data 9 Negeri'!H91/$D17,P_HAD),""),"") -> 0.70328472 | N17: =IF(AND($H17="YA",ISNUMBER($D17),ISNUMBER('Data 9 Negeri'!I91)),IFERROR(MIN('Data 9 Negeri'!I91/$D17,P_HAD),""),"") -> 0.75439553 | O17: =IF(AND($H17="YA",ISNUMBER($D17),ISNUMBER('Data 9 Negeri'!J91)),IFERROR(MIN('Data 9 Negeri'!J91/$D17,P_HAD),""),"") -> 1.6961974 | P17: =IF(AND($H17="YA",ISNUMBER($D17),ISNUMBER('Data 9 Negeri'!K91)),IFERROR(MIN('Data 9 Negeri'!K91/$D17,P_HAD),""),"") -> 0.72986234 | Q17: =IF(AND($H17="YA",ISNUMBER($D17),ISNUMBER('Data 9 Negeri'!L91)),IFERROR(MIN('Data 9 Negeri'!L91/$D17,P_HAD),""),"") -> 1.1162601 | R17: =IFERROR(AVERAGE(M17:Q17),"") -> 1 | S17: =IFERROR(AVERAGE(I17:L17),"") -> 2.1602835
... A28: 4.7 | B28: Pengurusan | C28: Perjawatan / pengurusan pegawai | D28: =IF(E28>=P_MINN,AVERAGE('Data 9 Negeri'!H102:L102),"") -> 1179.4 | E28: =COUNT('Data 9 Negeri'!H102:L102) -> 5 | F28: =COUNT('Data 9 Negeri'!D102:G102) -> 4 | H28: =IF(G28<>"",UPPER(TRIM(G28)),IF(AND(E28>=P_MINN,F28=4),"YA","TIDAK")) -> YA | I28: =IF(AND($H28="YA",ISNUMBER($D28),ISNUMBER('Data 9 Negeri'!D102)),IFERROR(MIN('Data 9 Negeri'!D102/$D28,P_HAD),""),"") -> 1.72291 | J28: =IF(AND($H28="YA",ISNUMBER($D28),ISNUMBER('Data 9 Negeri'!E102)),IFERROR(MIN('Data 9 Negeri'!E102/$D28,P_HAD),""),"") -> 1.8195693 | K28: =IF(AND($H28="YA",ISNUMBER($D28),ISNUMBER('Data 9 Negeri'!F102)),IFERROR(MIN('Data 9 Negeri'!F102/$D28,P_HAD),""),"") -> 1.2786162 | L28: =IF(AND($H28="YA",ISNUMBER($D28),ISNUMBER('Data 9 Negeri'!G102)),IFERROR(MIN('Data 9 Negeri'!G102/$D28,P_HAD),""),"") -> 1.0369679 | M28: =IF(AND($H28="YA",ISNUMBER($D28),ISNUMBER('Data 9 Negeri'!H102)),IFERROR(MIN('Data 9 Negeri'!H102/$D28,P_HAD),""),"") -> 1.1259963 | N28: =IF(AND($H28="YA",ISNUMBER($D28),ISNUMBER('Data 9 Negeri'!I102)),IFERROR(MIN('Data 9 Negeri'!I102/$D28,P_HAD),""),"") -> 0.98270307 | O28: =IF(AND($H28="YA",ISNUMBER($D28),ISNUMBER('Data 9 Negeri'!J102)),IFERROR(MIN('Data 9 Negeri'!J102/$D28,P_HAD),""),"") -> 1.006444 | P28: =IF(AND($H28="YA",ISNUMBER($D28),ISNUMBER('Data 9 Negeri'!K102)),IFERROR(MIN('Data 9 Negeri'!K102/$D28,P_HAD),""),"") -> 1.1132779 | Q28: =IF(AND($H28="YA",ISNUMBER($D28),ISNUMBER('Data 9 Negeri'!L102)),IFERROR(MIN('Data 9 Negeri'!L102/$D28,P_HAD),""),"") -> 0.77157877 | R28: =IFERROR(AVERAGE(M28:Q28),"") -> 1 | S28: =IFERROR(AVERAGE(I28:L28),"") -> 1.4645159
A30: SKOR KRITERIA (purata nisbah sub-kriteria yang diskor) | D30: Wajaran HQ | E30: Sub-kriteria diskor | F30: Jumlah sub-kriteria | I30: Sarawak | J30: Sabah | K30: Johor | L30: Perak | M30: Selangor | N30: Kedah | O30: Pahang | P30: Terengganu | Q30: Kelantan | R30: Purata sederhana | S30: Purata besar
A31: Pendidikan Awal Kanak-Kanak | D31: =W_PAKK -> 0.2 | E31: =COUNTIF(H6:H13,"YA") -> 8 | F31: =ROWS(H6:H13) -> 8 | I31: =IFERROR(AVERAGE(I6:I13),"") -> 1.6252125 | J31: =IFERROR(AVERAGE(J6:J13),"") -> 1.6718204 | K31: =IFERROR(AVERAGE(K6:K13),"") -> 1.3282628 | L31: =IFERROR(AVERAGE(L6:L13),"") -> 1.0184729 | M31: =IFERROR(AVERAGE(M6:M13),"") -> 1.1509974 | N31: =IFERROR(AVERAGE(N6:N13),"") -> 1.1094232 | O31: =IFERROR(AVERAGE(O6:O13),"") -> 0.95924429 | P31: =IFERROR(AVERAGE(P6:P13),"") -> 0.89039756 | Q31: =IFERROR(AVERAGE(Q6:Q13),"") -> 0.88993749 | R31: =IFERROR(AVERAGE(M31:Q31),"") -> 1 | S31: =IFERROR(AVERAGE(I31:L31),"") -> 1.4109422
A32: Kemahiran | D32: =W_KEM -> 0.15 | E32: =COUNTIF(H14:H17,"YA") -> 4 | F32: =ROWS(H14:H17) -> 4 | I32: =IFERROR(AVERAGE(I14:I17),"") -> 1.3513996 | J32: =IFERROR(AVERAGE(J14:J17),"") -> 2.2043669 | K32: =IFERROR(AVERAGE(K14:K17),"") -> 1.9332434 | L32: =IFERROR(AVERAGE(L14:L17),"") -> 1.7310968 | M32: =IFERROR(AVERAGE(M14:M17),"") -> 1.0822197 | N32: =IFERROR(AVERAGE(N14:N17),"") -> 0.69510719 | O32: =IFERROR(AVERAGE(O14:O17),"") -> 1.4028652 | P32: =IFERROR(AVERAGE(P14:P17),"") -> 0.82051469 | Q32: =IFERROR(AVERAGE(Q14:Q17),"") -> 0.99929317 | R32: =IFERROR(AVERAGE(M32:Q32),"") -> 1 | S32: =IFERROR(AVERAGE(I32:L32),"") -> 1.8050267
A33: Komuniti | D33: =W_KOM -> 0.15 | E33: =COUNTIF(H18:H21,"YA") -> 3 | F33: =ROWS(H18:H21) -> 4 | I33: =IFERROR(AVERAGE(I18:I21),"") -> 3.8946466 | J33: =IFERROR(AVERAGE(J18:J21),"") -> 2.0351392 | K33: =IFERROR(AVERAGE(K18:K21),"") -> 1.4660853 | L33: =IFERROR(AVERAGE(L18:L21),"") -> 1.2757149 | M33: =IFERROR(AVERAGE(M18:M21),"") -> 1.3375154 | N33: =IFERROR(AVERAGE(N18:N21),"") -> 1.5753343 | O33: =IFERROR(AVERAGE(O18:O21),"") -> 0.58506858 | P33: =IFERROR(AVERAGE(P18:P21),"") -> 0.68988634 | Q33: =IFERROR(AVERAGE(Q18:Q21),"") -> 0.86566299 | R33: =IFERROR(AVERAGE(M33:Q33),"") -> 1.0106935 | S33: =IFERROR(AVERAGE(I33:L33),"") -> 2.1678965
A34: Pengurusan | D34: =W_PENG -> 0.5 | E34: =COUNTIF(H22:H28,"YA") -> 2 | F34: =ROWS(H22:H28) -> 7 | I34: =IFERROR(AVERAGE(I22:I28),"") -> 2.126425 | J34: =IFERROR(AVERAGE(J22:J28),"") -> 1.4187667 | K34: =IFERROR(AVERAGE(K22:K28),"") -> 0.75407858 | L34: =IFERROR(AVERAGE(L22:L28),"") -> 1.6412385 | M34: =IFERROR(AVERAGE(M22:M28),"") -> 1.2566109 | N34: =IFERROR(AVERAGE(N22:N28),"") -> 1.115104 | O34: =IFERROR(AVERAGE(O22:O28),"") -> 1.1494296 | P34: =IFERROR(AVERAGE(P22:P28),"") -> 1.0157208 | Q34: =IFERROR(AVERAGE(Q22:Q28),"") -> 0.46313469 | R34: =IFERROR(AVERAGE(M34:Q34),"") -> 1 | S34: =IFERROR(AVERAGE(I34:L34),"") -> 1.4851272
A36: Jumlah (wajaran x skor kriteria) [pengiraan] | I36: =IF(ISNUMBER(I31),$D$31*I31,0)+IF(ISNUMBER(I32),$D$32*I32,0)+IF(ISNUMBER(I33),$D$33*I33,0)+IF(ISNUMBER(I34),$D$34*I34,0) -> 2.1751619 | J36: =IF(ISNUMBER(J31),$D$31*J31,0)+IF(ISNUMBER(J32),$D$32*J32,0)+IF(ISNUMBER(J33),$D$33*J33,0)+IF(ISNUMBER(J34),$D$34*J34,0) -> 1.6796733 | K36: =IF(ISNUMBER(K31),$D$31*K31,0)+IF(ISNUMBER(K32),$D$32*K32,0)+IF(ISNUMBER(K33),$D$33*K33,0)+IF(ISNUMBER(K34),$D$34*K34,0) -> 1.1525912 | L36: =IF(ISNUMBER(L31),$D$31*L31,0)+IF(ISNUMBER(L32),$D$32*L32,0)+IF(ISNUMBER(L33),$D$33*L33,0)+IF(ISNUMBER(L34),$D$34*L34,0) -> 1.4753356 | M36: =IF(ISNUMBER(M31),$D$31*M31,0)+IF(ISNUMBER(M32),$D$32*M32,0)+IF(ISNUMBER(M33),$D$33*M33,0)+IF(ISNUMBER(M34),$D$34*M34,0) -> 1.2214652 | N36: =IF(ISNUMBER(N31),$D$31*N31,0)+IF(ISNUMBER(N32),$D$32*N32,0)+IF(ISNUMBER(N33),$D$33*N33,0)+IF(ISNUMBER(N34),$D$34*N34,0) -> 1.1200029 | O36: =IF(ISNUMBER(O31),$D$31*O31,0)+IF(ISNUMBER(O32),$D$32*O32,0)+IF(ISNUMBER(O33),$D$33*O33,0)+IF(ISNUMBER(O34),$D$34*O34,0) -> 1.0647537 | P36: =IF(ISNUMBER(P31),$D$31*P31,0)+IF(ISNUMBER(P32),$D$32*P32,0)+IF(ISNUMBER(P33),$D$33*P33,0)+IF(ISNUMBER(P34),$D$34*P34,0) -> 0.91250007 | Q36: =IF(ISNUMBER(Q31),$D$31*Q31,0)+IF(ISNUMBER(Q32),$D$32*Q32,0)+IF(ISNUMBER(Q33),$D$33*Q33,0)+IF(ISNUMBER(Q34),$D$34*Q34,0) -> 0.68929827 | R36: =IFERROR(AVERAGE(M36:Q36),"") -> 1.001604 | S36: =IFERROR(AVERAGE(I36:L36),"") -> 1.6206905
A37: Jumlah wajaran kriteria yang ada skor [pengiraan] | I37: =IF(ISNUMBER(I31),$D$31,0)+IF(ISNUMBER(I32),$D$32,0)+IF(ISNUMBER(I33),$D$33,0)+IF(ISNUMBER(I34),$D$34,0) -> 1 | J37: =IF(ISNUMBER(J31),$D$31,0)+IF(ISNUMBER(J32),$D$32,0)+IF(ISNUMBER(J33),$D$33,0)+IF(ISNUMBER(J34),$D$34,0) -> 1 | K37: =IF(ISNUMBER(K31),$D$31,0)+IF(ISNUMBER(K32),$D$32,0)+IF(ISNUMBER(K33),$D$33,0)+IF(ISNUMBER(K34),$D$34,0) -> 1 | L37: =IF(ISNUMBER(L31),$D$31,0)+IF(ISNUMBER(L32),$D$32,0)+IF(ISNUMBER(L33),$D$33,0)+IF(ISNUMBER(L34),$D$34,0) -> 1 | M37: =IF(ISNUMBER(M31),$D$31,0)+IF(ISNUMBER(M32),$D$32,0)+IF(ISNUMBER(M33),$D$33,0)+IF(ISNUMBER(M34),$D$34,0) -> 1 | N37: =IF(ISNUMBER(N31),$D$31,0)+IF(ISNUMBER(N32),$D$32,0)+IF(ISNUMBER(N33),$D$33,0)+IF(ISNUMBER(N34),$D$34,0) -> 1 | O37: =IF(ISNUMBER(O31),$D$31,0)+IF(ISNUMBER(O32),$D$32,0)+IF(ISNUMBER(O33),$D$33,0)+IF(ISNUMBER(O34),$D$34,0) -> 1 | P37: =IF(ISNUMBER(P31),$D$31,0)+IF(ISNUMBER(P32),$D$32,0)+IF(ISNUMBER(P33),$D$33,0)+IF(ISNUMBER(P34),$D$34,0) -> 1 | Q37: =IF(ISNUMBER(Q31),$D$31,0)+IF(ISNUMBER(Q32),$D$32,0)+IF(ISNUMBER(Q33),$D$33,0)+IF(ISNUMBER(Q34),$D$34,0) -> 1 | R37: =IFERROR(AVERAGE(M37:Q37),"") -> 1 | S37: =IFERROR(AVERAGE(I37:L37),"") -> 1
A38: INDEKS KOMPOSIT SENARIO A | I38: =IFERROR(I36/I37,"") -> 2.1751619 | J38: =IFERROR(J36/J37,"") -> 1.6796733 | K38: =IFERROR(K36/K37,"") -> 1.1525912 | L38: =IFERROR(L36/L37,"") -> 1.4753356 | M38: =IFERROR(M36/M37,"") -> 1.2214652 | N38: =IFERROR(N36/N37,"") -> 1.1200029 | O38: =IFERROR(O36/O37,"") -> 1.0647537 | P38: =IFERROR(P36/P37,"") -> 0.91250007 | Q38: =IFERROR(Q36/Q37,"") -> 0.68929827 | R38: =IFERROR(AVERAGE(M38:Q38),"") -> 1.001604 | S38: =IFERROR(AVERAGE(I38:L38),"") -> 1.6206905
A39: Kedudukan (1 = beban tertinggi daripada 9) | I39: =IFERROR(RANK(I38,$I$38:$Q$38),"") -> 1 | J39: =IFERROR(RANK(J38,$I$38:$Q$38),"") -> 2 | K39: =IFERROR(RANK(K38,$I$38:$Q$38),"") -> 5 | L39: =IFERROR(RANK(L38,$I$38:$Q$38),"") -> 3 | M39: =IFERROR(RANK(M38,$I$38:$Q$38),"") -> 4 | N39: =IFERROR(RANK(N38,$I$38:$Q$38),"") -> 6 | O39: =IFERROR(RANK(O38,$I$38:$Q$38),"") -> 7 | P39: =IFERROR(RANK(P38,$I$38:$Q$38),"") -> 8 | Q39: =IFERROR(RANK(Q38,$I$38:$Q$38),"") -> 9
A40: Sub-kriteria diskor (daripada 23) | I40: =COUNT(I6:I28) -> 17 | J40: =COUNT(J6:J28) -> 17 | K40: =COUNT(K6:K28) -> 17 | L40: =COUNT(L6:L28) -> 17 | M40: =COUNT(M6:M28) -> 17 | N40: =COUNT(N6:N28) -> 16 | O40: =COUNT(O6:O28) -> 16 | P40: =COUNT(P6:P28) -> 17 | Q40: =COUNT(Q6:Q28) -> 17 | R40: =IFERROR(AVERAGE(M40:Q40),"") -> 16.6 | S40: =IFERROR(AVERAGE(I40:L40),"") -> 17
A41: Liputan berwajaran (bahagian kerangka HQ yang disokong data) | I41: =$D$31*COUNT(I6:I13)/ROWS(I6:I13)+$D$32*COUNT(I14:I17)/ROWS(I14:I17)+$D$33*COUNT(I18:I21)/ROWS(I18:I21)+$D$34*COUNT(I22:I28)/ROWS(I22:I28) -> 0.60535714 | J41: =$D$31*COUNT(J6:J13)/ROWS(J6:J13)+$D$32*COUNT(J14:J17)/ROWS(J14:J17)+$D$33*COUNT(J18:J21)/ROWS(J18:J21)+$D$34*COUNT(J22:J28)/ROWS(J22:J28) -> 0.60535714 | K41: =$D$31*COUNT(K6:K13)/ROWS(K6:K13)+$D$32*COUNT(K14:K17)/ROWS(K14:K17)+$D$33*COUNT(K18:K21)/ROWS(K18:K21)+$D$34*COUNT(K22:K28)/ROWS(K22:K28) -> 0.60535714 | L41: =$D$31*COUNT(L6:L13)/ROWS(L6:L13)+$D$32*COUNT(L14:L17)/ROWS(L14:L17)+$D$33*COUNT(L18:L21)/ROWS(L18:L21)+$D$34*COUNT(L22:L28)/ROWS(L22:L28) -> 0.60535714 | M41: =$D$31*COUNT(M6:M13)/ROWS(M6:M13)+$D$32*COUNT(M14:M17)/ROWS(M14:M17)+$D$33*COUNT(M18:M21)/ROWS(M18:M21)+$D$34*COUNT(M22:M28)/ROWS(M22:M28) -> 0.60535714 | N41: =$D$31*COUNT(N6:N13)/ROWS(N6:N13)+$D$32*COUNT(N14:N17)/ROWS(N14:N17)+$D$33*COUNT(N18:N21)/ROWS(N18:N21)+$D$34*COUNT(N22:N28)/ROWS(N22:N28) -> 0.56785714 | O41: =$D$31*COUNT(O6:O13)/ROWS(O6:O13)+$D$32*COUNT(O14:O17)/ROWS(O14:O17)+$D$33*COUNT(O18:O21)/ROWS(O18:O21)+$D$34*COUNT(O22:O28)/ROWS(O22:O28) -> 0.56785714 | P41: =$D$31*COUNT(P6:P13)/ROWS(P6:P13)+$D$32*COUNT(P14:P17)/ROWS(P14:P17)+$D$33*COUNT(P18:P21)/ROWS(P18:P21)+$D$34*COUNT(P22:P28)/ROWS(P22:P28) -> 0.60535714 | Q41: =$D$31*COUNT(Q6:Q13)/ROWS(Q6:Q13)+$D$32*COUNT(Q14:Q17)/ROWS(Q14:Q17)+$D$33*COUNT(Q18:Q21)/ROWS(Q18:Q21)+$D$34*COUNT(Q22:Q28)/ROWS(Q22:Q28) -> 0.60535714 | R41: =IFERROR(AVERAGE(M41:Q41),"") -> 0.59035714 | S41: =IFERROR(AVERAGE(I41:L41),"") -> 0.60535714
A42: Indeks tanpa Pengurusan (semakan kepekaan) | I42: =IFERROR((IF(ISNUMBER(I31),$D$31*I31,0)+IF(ISNUMBER(I32),$D$32*I32,0)+IF(ISNUMBER(I33),$D$33*I33,0))/(IF(ISNUMBER(I31),$D$31,0)+IF(ISNUMBER(I32),$D$32,0)+IF(ISNUMBER(I33),$D$33,0)),"") -> 2.2238989 | J42: =IFERROR((IF(ISNUMBER(J31),$D$31*J31,0)+IF(ISNUMBER(J32),$D$32*J32,0)+IF(ISNUMBER(J33),$D$33*J33,0))/(IF(ISNUMBER(J31),$D$31,0)+IF(ISNUMBER(J32),$D$32,0)+IF(ISNUMBER(J33),$D$33,0)),"") -> 1.94058 | K42: =IFERROR((IF(ISNUMBER(K31),$D$31*K31,0)+IF(ISNUMBER(K32),$D$32*K32,0)+IF(ISNUMBER(K33),$D$33*K33,0))/(IF(ISNUMBER(K31),$D$31,0)+IF(ISNUMBER(K32),$D$32,0)+IF(ISNUMBER(K33),$D$33,0)),"") -> 1.5511037 | L42: =IFERROR((IF(ISNUMBER(L31),$D$31*L31,0)+IF(ISNUMBER(L32),$D$32*L32,0)+IF(ISNUMBER(L33),$D$33*L33,0))/(IF(ISNUMBER(L31),$D$31,0)+IF(ISNUMBER(L32),$D$32,0)+IF(ISNUMBER(L33),$D$33,0)),"") -> 1.3094327 | M42: =IFERROR((IF(ISNUMBER(M31),$D$31*M31,0)+IF(ISNUMBER(M32),$D$32*M32,0)+IF(ISNUMBER(M33),$D$33*M33,0))/(IF(ISNUMBER(M31),$D$31,0)+IF(ISNUMBER(M32),$D$32,0)+IF(ISNUMBER(M33),$D$33,0)),"") -> 1.1863195 | N42: =IFERROR((IF(ISNUMBER(N31),$D$31*N31,0)+IF(ISNUMBER(N32),$D$32*N32,0)+IF(ISNUMBER(N33),$D$33*N33,0))/(IF(ISNUMBER(N31),$D$31,0)+IF(ISNUMBER(N32),$D$32,0)+IF(ISNUMBER(N33),$D$33,0)),"") -> 1.1249017 | O42: =IFERROR((IF(ISNUMBER(O31),$D$31*O31,0)+IF(ISNUMBER(O32),$D$32*O32,0)+IF(ISNUMBER(O33),$D$33*O33,0))/(IF(ISNUMBER(O31),$D$31,0)+IF(ISNUMBER(O32),$D$32,0)+IF(ISNUMBER(O33),$D$33,0)),"") -> 0.98007785 | P42: =IFERROR((IF(ISNUMBER(P31),$D$31*P31,0)+IF(ISNUMBER(P32),$D$32*P32,0)+IF(ISNUMBER(P33),$D$33*P33,0))/(IF(ISNUMBER(P31),$D$31,0)+IF(ISNUMBER(P32),$D$32,0)+IF(ISNUMBER(P33),$D$33,0)),"") -> 0.80927933 | Q42: =IFERROR((IF(ISNUMBER(Q31),$D$31*Q31,0)+IF(ISNUMBER(Q32),$D$32*Q32,0)+IF(ISNUMBER(Q33),$D$33*Q33,0))/(IF(ISNUMBER(Q31),$D$31,0)+IF(ISNUMBER(Q32),$D$32,0)+IF(ISNUMBER(Q33),$D$33,0)),"") -> 0.91546185 | R42: =IFERROR(AVERAGE(M42:Q42),"") -> 1.0032081 | S42: =IFERROR(AVERAGE(I42:L42),"") -> 1.7562538
